Workbook

Sheet Algorithm
A1: MARS 1-LB CATALOG · n = 1 + 0
A2: Catalog index never starts at zero. First slot is n = 1. Offset is 0. n = 1 + 0.
A4: RULE | B4: n ≠ 0. n = 1 + 0. Every catalog row is addressed by a positive integer index.
A6: Symbol | B6: Meaning | C6: Value / formula | D6: Notes
A7: n | B7: Catalog index | C7: 1, 2, 3, … | D7: Row address. Never 0.
A8: n0 | B8: Offset | C8: 0 | D8: Added so the first item is 1, not 0.
A9: n_start | B9: First legal index | C9: =1+0 -> 1 | D9: Hard rule of this matrix.
A10: m_i | B10: Catalog pounds of item i | C10: input (blue) | D10: Mass expressed in 1-lb units. May be decimal.
A11: p_i | B11: Packet ceiling | C11: CEILING(m_i, 1) | D11: If you later packetize. Catalog itself allows fractions.
A12: k_i | B12: Assembly width | C12: input | D12: How many catalog-lb units form one useful assembled object.
A13: class_i | B13: Could-go class | C13: Core / Enabling / Optional | D13: Not a flight commitment.
A16: INDEX CONSTRUCTION
A17: Row i on the Catalog sheet is addressed as n = i, with i starting at 1. There is no row 0 and no item 0. Empty is not an index. n = 1 + 0 is the generator: start at one, add a zero offset, never decrement to zero. New items append at n_max + 1. Deleting an item retires the number; it is not reused as 0.
A22: This workbook catalogs infrastructure that COULD go to Mars. It is not a flight manifest.

Sheet Catalog
A1: MARS INFRASTRUCTURE CATALOG · unit = 1 pound · index n = 1 + 0
A2: Could-go inventory only. Blue cells are inputs. Black cells are formulas. n never equals 0.
A3: n | B3: Category | C3: Item | D3: Catalog lb m_i | E3: Packet ceil p_i | F3: Assembly k | G3: Could-go class | H3: Depends on (n) | I3: Enables | J3: Notes | K3: Running lb | L3: Running packets
A4: 1 | B4: Habitat | C4: Unpressurized deck tile | D4: 1 | E4: =CEILING(D4,1) -> 1 | F4: 4 | G4: Core | H4: — | I4: Floor / wall grid | J4: 1-lb base plate | K4: =D4 -> 1 | L4: =E4 -> 1
A5: 2 | B5: Habitat | C5: Pressure panel | D5: 8 | E5: =CEILING(D5,1) -> 8 | F5: 4 | G5: Core | H5: 1 | I5: Livable volume | J5: Needs seals + frame | K5: =K4+D5 -> 9 | L5: =L4+E5 -> 9
A6: 3 | B6: Habitat | C6: Airlock collar | D6: 18 | E6: =CEILING(D6,1) -> 18 | F6: 1 | G6: Enabling | H6: 2 | I6: EVA / transfer | K6: =K5+D6 -> 27 | L6: =L5+E6 -> 27
A7: 4 | B7: Habitat | C7: Window / viewport brick | D7: 6 | E7: =CEILING(D7,1) -> 6 | F7: 1 | G7: Optional | H7: 2 | I7: Sightline | K7: =K6+D7 -> 33 | L7: =L6+E7 -> 33
A8: 5 | B8: Power | C8: Solar brick | D8: 1 | E8: =CEILING(D8,1) -> 1 | F8: 8 | G8: Core | H8: — | I8: Trickle charge | J8: Dust-tolerant face | K8: =K7+D8 -> 34 | L8: =L7+E8 -> 34
A9: 6 | B9: Power | C9: Battery brick | D9: 2 | E9: =CEILING(D9,1) -> 2 | F9: 8 | G9: Core | H9: 5 | I9: Night ops | K9: =K8+D9 -> 36 | L9: =L8+E9 -> 36
A10: 7 | B10: Power | C10: Power bus node | D10: 3 | E10: =CEILING(D10,1) -> 3 | F10: 2 | G10: Enabling | H10: 5,6 | I10: Distribution | K10: =K9+D10 -> 39 | L10: =L9+E10 -> 39
A11: 8 | B11: Power | C11: Small RTG / nuke brick (concept) | D11: 25 | E11: =CEILING(D11,1) -> 25 | F11: 1 | G11: Optional | H11: 7 | I11: Base load | J11: Catalog only — not a build plan | K11: =K10+D11 -> 64 | L11: =L10+E11 -> 64
A12: 9 | B12: Mobility | C12: Wheel / drive packet | D12: 4 | E12: =CEILING(D12,1) -> 4 | F12: 4 | G12: Enabling | H12: 10 | I12: Motion | K12: =K11+D12 -> 68 | L12: =L11+E12 -> 68
A13: 10 | B13: Mobility | C13: Small rover chassis | D13: 25 | E13: =CEILING(D13,1) -> 25 | F13: 1 | G13: Enabling | H13: 9,11 | I13: Local haul | K13: =K12+D13 -> 93 | L13: =L12+E13 -> 93
A14: 11 | B14: Mobility | C14: Compute / nav brick | D14: 3 | E14: =CEILING(D14,1) -> 3 | F14: 1 | G14: Enabling | H14: — | I14: Drive + pose | K14: =K13+D14 -> 96 | L14: =L13+E14 -> 96
A15: 12 | B15: Mobility | C15: Manipulator arm segment | D15: 7 | E15: =CEILING(D15,1) -> 7 | F15: 3 | G15: Optional | H15: 10 | I15: Pick / place | K15: =K14+D15 -> 103 | L15: =L14+E15 -> 103
A16: 13 | B16: Life support | C16: Water recycler brick | D16: 12 | E16: =CEILING(D16,1) -> 12 | F16: 1 | G16: Core | H16: 6,7 | I16: Crew days | K16: =K15+D16 -> 115 | L16: =L15+E16 -> 115
A17: 14 | B17: Life support | C17: O2 / CO2 cartridge | D17: 2 | E17: =CEILING(D17,1) -> 2 | F17: 6 | G17: Core | H17: 13 | I17: Breathing loop | K17: =K16+D17 -> 117 | L17: =L16+E17 -> 117
A18: 15 | B18: Life support | C18: Tank / bladder | D18: 5 | E18: =CEILING(D18,1) -> 5 | F18: 2 | G18: Enabling | H18: 13 | I18: Store water | K18: =K17+D18 -> 122 | L18: =L17+E18 -> 122
A19: 16 | B19: Life support | C19: Thermal garment pack | D19: 4 | E19: =CEILING(D19,1) -> 4 | F19: 2 | G19: Optional | H19: — | I19: EVA / night | K19: =K18+D19 -> 126 | L19: =L18+E19 -> 126
A20: 17 | B20: Comms | C20: Surface relay | D20: 15 | E20: =CEILING(D20,1) -> 15 | F20: 1 | G20: Core | H20: 6,7 | I20: Link home / site | K20: =K19+D20 -> 141 | L20: =L19+E20 -> 141
A21: 18 | B21: Comms | C21: Local mesh node | D21: 1 | E21: =CEILING(D21,1) -> 1 | F21: 8 | G21: Enabling | H21: 17 | I21: Packet radio grid | J21: 1-lb radio | K21: =K20+D21 -> 142 | L21: =L20+E21 -> 142
A22: 19 | B22: Comms | C22: Nav beacon | D22: 2 | E22: =CEILING(D22,1) -> 2 | F22: 4 | G22: Enabling | H22: 18 | I22: Site fix | K22: =K21+D22 -> 144 | L22: =L21+E22 -> 144
A23: 20 | B23: Manufacture | C23: ISRU feedstock bag | D23: 1 | E23: =CEILING(D23,1) -> 1 | F23: 20 | G23: Enabling | H23: — | I23: Print / sinter | J23: Regolith or resin | K23: =K22+D23 -> 145 | L23: =L22+E23 -> 145
A24: 21 | B24: Manufacture | C24: Print head brick | D24: 9 | E24: =CEILING(D24,1) -> 9 | F24: 1 | G24: Optional | H24: 6,20 | I24: Make parts | K24: =K23+D24 -> 154 | L24: =L23+E24 -> 154
A25: 22 | B25: Manufacture | C25: Sinter / kiln brick | D25: 14 | E25: =CEILING(D25,1) -> 14 | F25: 1 | G25: Optional | H25: 6,20 | I25: Brick / tile from dirt | K25: =K24+D25 -> 168 | L25: =L24+E25 -> 168
A26: 23 | B26: Science | C26: Weather / dust station | D26: 3 | E26: =CEILING(D26,1) -> 3 | F26: 1 | G26: Enabling | H26: 6,18 | I26: Site data | K26: =K25+D26 -> 171 | L26: =L25+E26 -> 171
A27: 24 | B27: Science | C27: Seismic pin | D27: 1 | E27: =CEILING(D27,1) -> 1 | F27: 4 | G27: Optional | H27: 18 | I27: Ground motion | K27: =K26+D27 -> 172 | L27: =L26+E27 -> 172
A28: 25 | B28: Science | C28: Sample cache tube | D28: 1 | E28: =CEILING(D28,1) -> 1 | F28: 12 | G28: Optional | H28: 12 | I28: Return / store | K28: =K27+D28 -> 173 | L28: =L27+E28 -> 173
A29: 26 | B29: Safety | C29: Repair tool kit | D29: 6 | E29: =CEILING(D29,1) -> 6 | F29: 1 | G29: Core | H29: — | I29: Keep other items alive | K29: =K28+D29 -> 179 | L29: =L28+E29 -> 179
A30: 27 | B30: Safety | C30: Patch / seal kit | D30: 2 | E30: =CEILING(D30,1) -> 2 | F30: 4 | G30: Core | H30: 2 | I30: Pressure repair | K30: =K29+D30 -> 181 | L30: =L29+E30 -> 181
A31: 28 | B31: Safety | C31: Fire / dust suppress pack | D31: 5 | E31: =CEILING(D31,1) -> 5 | F31: 2 | G31: Enabling | H31: — | I31: Site safety | K31: =K30+D31 -> 186 | L31: =L30+E31 -> 186
A32: 29 | B32: Safety | C32: Med / trauma brick | D32: 8 | E32: =CEILING(D32,1) -> 8 | F32: 1 | G32: Optional | H32: — | I32: Crew care | K32: =K31+D32 -> 194 | L32: =L31+E32 -> 194
A33: 30 | B33: Habitat | C33: Sleep / berth frame | D33: 16 | E33: =CEILING(D33,1) -> 16 | F33: 1 | G33: Optional | H33: 1,2 | I33: Crew rest | K33: =K32+D33 -> 210 | L33: =L32+E33 -> 210
A34: 31 | B34: Habitat | C34: Galley brick | D34: 11 | E34: =CEILING(D34,1) -> 11 | F34: 1 | G34: Optional | H34: 6,15 | I34: Food prep | K34: =K33+D34 -> 221 | L34: =L33+E34 -> 221
A35: 32 | B35: Power | C35: Cable spool 50 m | D35: 4 | E35: =CEILING(D35,1) -> 4 | F35: 2 | G35: Enabling | H35: 7 | I35: Run power | K35: =K34+D35 -> 225 | L35: =L34+E35 -> 225
A36: 33 | B36: Mobility | C36: Trailer / pallet | D36: 10 | E36: =CEILING(D36,1) -> 10 | F36: 2 | G36: Optional | H36: 10 | I36: Haul packets | K36: =K35+D36 -> 235 | L36: =L35+E36 -> 235
A37: 34 | B37: Manufacture | C37: Fastener / interface pack | D37: 1 | E37: =CEILING(D37,1) -> 1 | F37: 10 | G37: Core | H37: — | I37: Join any two items | J37: Standard 1-lb join kit | K37: =K36+D37 -> 236 | L37: =L36+E37 -> 236
A38: 35 | B38: Comms | C38: High-gain dish segment | D38: 12 | E38: =CEILING(D38,1) -> 12 | F38: 1 | G38: Optional | H38: 17 | I38: Earth link margin | K38: =K37+D38 -> 248 | L38: =L37+E38 -> 248
A39: 36 | B39: Science | C39: Camera / mast brick | D39: 4 | E39: =CEILING(D39,1) -> 4 | F39: 1 | G39: Optional | H39: 11 | I39: Survey | K39: =K38+D39 -> 252 | L39: =L38+E39 -> 252
A40: 37 | B40: Life support | C40: Plant / grow tray | D40: 6 | E40: =CEILING(D40,1) -> 6 | F40: 2 | G40: Optional | H40: 5,15 | I40: Fresh mass | K40: =K39+D40 -> 258 | L40: =L39+E40 -> 258
...

Sheet Category matrix
A1: CATEGORY × CLASS MATRIX
A3: Category | B3: Core lb | C3: Enabling lb | D3: Optional lb | E3: Total lb | F3: Item count
A4: Habitat | B4: =SUMIFS(Catalog!D:D,Catalog!B:B,A4,Catalog!G:G,"Core") -> 9 | C4: =SUMIFS(Catalog!D:D,Catalog!B:B,A4,Catalog!G:G,"Enabling") -> 21 | D4: =SUMIFS(Catalog!D:D,Catalog!B:B,A4,Catalog!G:G,"Optional") -> 61 | E4: =B4+C4+D4 -> 91 | F4: =COUNTIF(Catalog!B:B,A4) -> 9
A5: Power | B5: =SUMIFS(Catalog!D:D,Catalog!B:B,A5,Catalog!G:G,"Core") -> 3 | C5: =SUMIFS(Catalog!D:D,Catalog!B:B,A5,Catalog!G:G,"Enabling") -> 7 | D5: =SUMIFS(Catalog!D:D,Catalog!B:B,A5,Catalog!G:G,"Optional") -> 30 | E5: =B5+C5+D5 -> 40 | F5: =COUNTIF(Catalog!B:B,A5) -> 7
A6: Mobility | B6: =SUMIFS(Catalog!D:D,Catalog!B:B,A6,Catalog!G:G,"Core") -> 0 | C6: =SUMIFS(Catalog!D:D,Catalog!B:B,A6,Catalog!G:G,"Enabling") -> 32 | D6: =SUMIFS(Catalog!D:D,Catalog!B:B,A6,Catalog!G:G,"Optional") -> 25 | E6: =B6+C6+D6 -> 57 | F6: =COUNTIF(Catalog!B:B,A6) -> 6
A7: Life support | B7: =SUMIFS(Catalog!D:D,Catalog!B:B,A7,Catalog!G:G,"Core") -> 14 | C7: =SUMIFS(Catalog!D:D,Catalog!B:B,A7,Catalog!G:G,"Enabling") -> 14 | D7: =SUMIFS(Catalog!D:D,Catalog!B:B,A7,Catalog!G:G,"Optional") -> 10 | E7: =B7+C7+D7 -> 38 | F7: =COUNTIF(Catalog!B:B,A7) -> 6
A8: Comms | B8: =SUMIFS(Catalog!D:D,Catalog!B:B,A8,Catalog!G:G,"Core") -> 15 | C8: =SUMIFS(Catalog!D:D,Catalog!B:B,A8,Catalog!G:G,"Enabling") -> 3 | D8: =SUMIFS(Catalog!D:D,Catalog!B:B,A8,Catalog!G:G,"Optional") -> 14 | E8: =B8+C8+D8 -> 32 | F8: =COUNTIF(Catalog!B:B,A8) -> 5
A9: Manufacture | B9: =SUMIFS(Catalog!D:D,Catalog!B:B,A9,Catalog!G:G,"Core") -> 2 | C9: =SUMIFS(Catalog!D:D,Catalog!B:B,A9,Catalog!G:G,"Enabling") -> 1 | D9: =SUMIFS(Catalog!D:D,Catalog!B:B,A9,Catalog!G:G,"Optional") -> 30 | E9: =B9+C9+D9 -> 33 | F9: =COUNTIF(Catalog!B:B,A9) -> 6
A10: Science | B10: =SUMIFS(Catalog!D:D,Catalog!B:B,A10,Catalog!G:G,"Core") -> 0 | C10: =SUMIFS(Catalog!D:D,Catalog!B:B,A10,Catalog!G:G,"Enabling") -> 3 | D10: =SUMIFS(Catalog!D:D,Catalog!B:B,A10,Catalog!G:G,"Optional") -> 7 | E10: =B10+C10+D10 -> 10 | F10: =COUNTIF(Catalog!B:B,A10) -> 5
A11: Safety | B11: =SUMIFS(Catalog!D:D,Catalog!B:B,A11,Catalog!G:G,"Core") -> 8 | C11: =SUMIFS(Catalog!D:D,Catalog!B:B,A11,Catalog!G:G,"Enabling") -> 9 | D11: =SUMIFS(Catalog!D:D,Catalog!B:B,A11,Catalog!G:G,"Optional") -> 8 | E11: =B11+C11+D11 -> 25 | F11: =COUNTIF(Catalog!B:B,A11) -> 6
A12: ALL | B12: =SUM(B4:B11) -> 51 | C12: =SUM(C4:C11) -> 90 | D12: =SUM(D4:D11) -> 185 | E12: =SUM(E4:E11) -> 326 | F12: =SUM(F4:F11) -> 50
A32: How to read
A33: Each category is the sum of catalog pounds sitting in that class. Core = needed for a minimal useful site. Enabling = unlocks Core to actually work. Optional = quality, science, comfort, extra margin. None of these rows are a commitment to fly.

Sheet How to add
A1: ADD A ROW WITHOUT BREAKING n = 1 + 0
A3: 1. Next empty n on Catalog is already numbered (51–60 reserved).
A4: 2. Fill Category, Item, Catalog lb (blue), Assembly k (blue), class, depends, enables, notes.
A5: 3. Do not put anything in row index 0. Do not renumber existing n downward.
A6: 4. If an item is retired, keep its n and mark class or notes “retired”. Do not collapse to zero.
A7: 5. Depends-on uses other n values (example: 5,6). Use — if it depends on nothing.
A8: 6. Category matrix and totals update from the Catalog sheet automatically.
A9: 7. Catalog lb may be a decimal (0.25 sensor). Packet ceil always rounds up to a whole pound.
A10: 8. This file is the could-go matrix. A later flight pick-list is a filter on class + n, not a new index system.
A13: Generator check | B13: =Algorithm!C9 -> 1 | C13: must be 1
